WARNING  pytest_result_log:plugin.py:122 Start: testcase/test07.py::test_sea_file_login[seafile@admin.com666-admin-400-Unable to login with provided credentials]
WARNING  pytest_result_log:plugin.py:128 End: testcase/test07.py::test_sea_file_login[seafile@admin.com666-admin-400-Unable to login with provided credentials]